<?xml version="1.0" encoding="UTF-8"?>
<testsuite errors="1" failures="0" name="unittest.loader._FailedTest-20190411021908" skipped="0" tests="1" time="0.000" timestamp="2019-04-11T02:19:08">
	<testcase classname="unittest.loader._FailedTest" name="helloworld_tests" time="0.000" timestamp="2019-04-11T02:19:08">
		<error message="Failed to import test module: helloworld_tests
Traceback (most recent call last):
  File &quot;/home/gaurav/anaconda3/lib/python3.7/unittest/loader.py&quot;, line 154, in loadTestsFromName
    module = __import__(module_name)
  File &quot;/home/gaurav/demo/src/unittest/python/helloworld_tests.py&quot;, line 1, in &lt;module&gt;
    from mockito import mock, verify
ModuleNotFoundError: No module named 'mockito'
" type="ImportError">
<![CDATA[ImportError: Failed to import test module: helloworld_tests
Traceback (most recent call last):
  File "/home/gaurav/anaconda3/lib/python3.7/unittest/loader.py", line 154, in loadTestsFromName
    module = __import__(module_name)
  File "/home/gaurav/demo/src/unittest/python/helloworld_tests.py", line 1, in <module>
    from mockito import mock, verify
ModuleNotFoundError: No module named 'mockito'

]]>		</error>
	</testcase>
	<system-out>
<![CDATA[]]>	</system-out>
	<system-err>
<![CDATA[]]>	</system-err>
</testsuite>
